<?xml version="1.0" encoding="utf-8"?>
<!-- This URDF was automatically created by SolidWorks to URDF Exporter! Originally created by Stephen Brawner (brawner@gmail.com) 
     Commit Version: 1.6.0-1-g15f4949  Build Version: 1.6.7594.29634
     For more information, please see http://wiki.ros.org/sw_urdf_exporter -->
<robot
  name="rboot_rviz2">
  <link name="world" />
  <joint name="world_joint" type="fixed">
    <parent link="world" />
    <child link = "base_link" />
    <origin xyz="0.0 0.0 0.0" rpy="3.1415926536 3.1415926536 0.0" />
  </joint>
  <!-- ROS base_link to ROCR6 'Base' Coordinates transform -->
    <link name="base"/>
    <joint name="base_link-base_fixed_joint" type="fixed">
      <!-- NOTE: this rotation is only needed as long as base_link itself is
                 not corrected wrt the real robot (ie: rotated over 180
                 degrees)
      -->
      <origin xyz="0 0 0" rpy="0 0 -3.1415926536"/>
      <parent link="base_link"/>
      <child link="base"/>
    </joint>

  <link
    name="base_link">
    <inertial>
      <origin
        xyz="-0.00077713 -1.109E-07 0.029981"
        rpy="0 0 0" />
      <!-- to keep it stable in gazebo -->
      <mass
        value="500" />
      <inertia
        ixx="0.00032444"
        ixy="6.1577E-11"
        ixz="-1.533E-06"
        iyy="0.00030598"
        iyz="-1.3121E-10"
        izz="0.00047422" />
    </inertial>
    <visual>
      <origin
        xyz="0 0 0"
        rpy="0 0 0" />
      <geometry>
        <mesh
          filename="package://rboot_rviz2/meshes/base_link.STL" />
      </geometry>
      <material
        name="">
        <color
          rgba="0.75294 0.75294 0.75294 1" />
      </material>
    </visual>
    <collision>
      <origin
        xyz="0 0 0"
        rpy="0 0 0" />
      <geometry>
        <mesh
          filename="package://rboot_rviz2/meshes/base_link.STL" />
      </geometry>
    </collision>
  </link>
  <link
    name="shoulder_link">
    <inertial>
      <origin
        xyz="0.012267 -2.6409E-06 -0.016591"
        rpy="0 0 0" />
      <mass
        value="0.017622" />
      <inertia
        ixx="1.6837E-06"
        ixy="-1.5204E-13"
        ixz="-6.5082E-13"
        iyy="1.5626E-06"
        iyz="2.8285E-14"
        izz="2.4948E-06" />
    </inertial>
    <visual>
      <origin
        xyz="0 0 0"
        rpy="0 0 0" />
      <geometry>
        <mesh
          filename="package://rboot_rviz2/meshes/shoulder_link.STL" />
      </geometry>
      <material
        name="">
        <color
          rgba="0.75294 0.75294 0.75294 1" />
      </material>
    </visual>
    <collision>
      <origin
        xyz="0 0 0"
        rpy="0 0 0" />
      <geometry>
        <mesh
          filename="package://rboot_rviz2/meshes/shoulder_link.STL" />
      </geometry>
    </collision>
  </link>
  <joint
    name="shoulder_pan_joint"
    type="revolute">
                <command_interface name="position"/>
                <state_interface name="position">
                  <param name="initial_value">0</param>
                </state_interface>
                <state_interface name="velocity"/>
    <origin
      xyz="0 0 0.09264"
      rpy="0 0 0" />
    <parent
      link="base_link" />
    <child
      link="shoulder_link" />
    <axis
      xyz="0 0 -1" />
    <limit
      lower="-3.14"
      upper="3.14"
      effort="150"
      velocity="3.15" />
  </joint>
  <link
    name="upper_arm_link">
    <inertial>
      <origin
        xyz="-0.01014 0.0001634 0.0845"
        rpy="0 0 0" />
      <mass
        value="0.057671" />
      <inertia
        ixx="2.7066E-05"
        ixy="1.8312E-12"
        ixz="1.4277E-09"
        iyy="2.5201E-05"
        iyz="-2.8108E-08"
        izz="1.0656E-05" />
    </inertial>
    <visual>
      <origin
        xyz="0 0 0"
        rpy="0 0 0" />
      <geometry>
        <mesh
          filename="package://rboot_rviz2/meshes/upper_arm_link.STL" />
      </geometry>
      <material
        name="">
        <color
          rgba="0.75294 0.75294 0.75294 1" />
      </material>
    </visual>
    <collision>
      <origin
        xyz="0 0 0"
        rpy="0 0 0" />
      <geometry>
        <mesh
          filename="package://rboot_rviz2/meshes/upper_arm_link.STL" />
      </geometry>
    </collision>
  </link>
  <joint
    name="shoulder_lift_joint"
    type="revolute">
                <command_interface name="position"/>
                <state_interface name="position">
                  <param name="initial_value">0</param>
                </state_interface>
                <state_interface name="velocity"/>
    <origin
      xyz="0.07504 0 0"
      rpy="0 0 0" />
    <parent
      link="shoulder_link" />
    <child
      link="upper_arm_link" />
    <axis
      xyz="-1 0 0" />
    <limit
      lower="-3.14"
      upper="3.14"
      effort="150"
      velocity="3.15" />
  </joint>
  <link
    name="forearm_link">
    <inertial>
      <origin
        xyz="0.00366311337482465 -0.000150592222610524 0.0591863605094726"
        rpy="0 0 0" />
      <mass
        value="0.0789411947978663" />
      <inertia
        ixx="3.58261155296285E-05"
        ixy="-3.78445209588342E-10"
        ixz="-7.45608835026796E-08"
        iyy="3.18001708921501E-05"
        iyz="8.79717930933106E-08"
        izz="1.7131622282654E-05" />
    </inertial>
    <visual>
      <origin
        xyz="0 0 0"
        rpy="0 0 0" />
      <geometry>
        <mesh
          filename="package://rboot_rviz2/meshes/forearm_link.STL" />
      </geometry>
      <material
        name="">
        <color
          rgba="0.752941176470588 0.752941176470588 0.752941176470588 1" />
      </material>
    </visual>
    <collision>
      <origin
        xyz="0 0 0"
        rpy="0 0 0" />
      <geometry>
        <mesh
          filename="package://rboot_rviz2/meshes/forearm_link.STL" />
      </geometry>
    </collision>
  </link>
  <joint
    name="elbow_joint"
    type="revolute">
                <command_interface name="position"/>
                <state_interface name="position">
                  <param name="initial_value">0</param>
                </state_interface>
                <state_interface name="velocity"/>
    <origin
      xyz="-0.05864 0.00032379 0.16839"
      rpy="0 0 0" />
    <parent
      link="upper_arm_link" />
    <child
      link="forearm_link" />
    <axis
      xyz="-1 0 0" />
    <limit
      lower="-3.14"
      upper="3.14"
      effort="150"
      velocity="3.15" />
  </joint>
  <link
    name="wrist_1_link">
    <inertial>
      <origin
        xyz="0.066636 -2.6409E-06 0.016591"
        rpy="0 0 0" />
      <mass
        value="0.017622" />
      <inertia
        ixx="1.6837E-06"
        ixy="1.5204E-13"
        ixz="-6.5082E-13"
        iyy="1.5626E-06"
        iyz="-2.8285E-14"
        izz="2.4948E-06" />
    </inertial>
    <visual>
      <origin
        xyz="0 0 0"
        rpy="0 0 0" />
      <geometry>
        <mesh
          filename="package://rboot_rviz2/meshes/wrist_1_link.STL" />
      </geometry>
      <material
        name="">
        <color
          rgba="0.75294 0.75294 0.75294 1" />
      </material>
    </visual>
    <collision>
      <origin
        xyz="0 0 0"
        rpy="0 0 0" />
      <geometry>
        <mesh
          filename="package://rboot_rviz2/meshes/wrist_1_link.STL" />
      </geometry>
    </collision>
  </link>
  <joint
    name="wrist_1_joint"
    type="revolute">
                <command_interface name="position"/>
                <state_interface name="position">
                  <param name="initial_value">0</param>
                </state_interface>
                <state_interface name="velocity"/>
    <origin
      xyz="-0.015463 0.0003287 0.16902"
      rpy="0 0 0" />
    <parent
      link="forearm_link" />
    <child
      link="wrist_1_link" />
    <axis
      xyz="1 0 0" />
    <limit
      lower="-3.14"
      upper="3.14"
      effort="28"
      velocity="3.2" />
  </joint>
  <link
    name="wrist_2_link">
                <command_interface name="position"/>
                <state_interface name="position">
                  <param name="initial_value">0</param>
                </state_interface>
                <state_interface name="velocity"/>
    <inertial>
      <origin
        xyz="0.016591 2.6409E-06 0.062873"
        rpy="0 0 0" />
      <mass
        value="0.017622" />
      <inertia
        ixx="2.4948E-06"
        ixy="2.8285E-14"
        ixz="-6.5082E-13"
        iyy="1.5626E-06"
        iyz="-1.5204E-13"
        izz="1.6837E-06" />
    </inertial>
    <visual>
      <origin
        xyz="0 0 0"
        rpy="0 0 0" />
      <geometry>
        <mesh
          filename="package://rboot_rviz2/meshes/wrist_2_link.STL" />
      </geometry>
      <material
        name="">
        <color
          rgba="0.75294 0.75294 0.75294 1" />
      </material>
    </visual>
    <collision>
      <origin
        xyz="0 0 0"
        rpy="0 0 0" />
      <geometry>
        <mesh
          filename="package://rboot_rviz2/meshes/wrist_2_link.STL" />
      </geometry>
    </collision>
  </link>
  <joint
    name="wrist_2_joint"
    type="revolute">
                <command_interface name="position"/>
                <state_interface name="position">
                  <param name="initial_value">0</param>
                </state_interface>
                <state_interface name="velocity"/>
    <origin
      xyz="0.078903 0 0"
      rpy="0 0 0" />
    <parent
      link="wrist_1_link" />
    <child
      link="wrist_2_link" />
    <axis
      xyz="0 0 1" />
    <limit
      lower="-3.14"
      upper="3.14"
      effort="28"
      velocity="3.2" />
  </joint>
  <link
    name="wrist_3_link">
    <inertial>
      <origin
        xyz="0.03264 -8.9866E-14 -8.8818E-16"
        rpy="0 0 0" />
      <mass
        value="0.0022885" />
      <inertia
        ixx="4.4939E-07"
        ixy="4.4878E-21"
        ixz="4.4511E-22"
        iyy="2.2546E-07"
        iyz="-5.9284E-23"
        izz="2.2546E-07" />
    </inertial>
    <visual>
      <origin
        xyz="0 0 0"
        rpy="0 0 0" />
      <geometry>
        <mesh
          filename="package://rboot_rviz2/meshes/wrist_3_link.STL" />
      </geometry>
      <material
        name="">
        <color
          rgba="0.75294 0.75294 0.75294 1" />
      </material>
    </visual>
    <collision>
      <origin
        xyz="0 0 0"
        rpy="0 0 0" />
      <geometry>
        <mesh
          filename="package://rboot_rviz2/meshes/wrist_3_link.STL" />
      </geometry>
    </collision>
  </link>
  <joint
    name="wrist_3_joint"
    type="revolute">
                <command_interface name="position"/>
                <state_interface name="position">
                  <param name="initial_value">0</param>
                </state_interface>
                <state_interface name="velocity"/>
    <origin
      xyz="0 0 0.07514"
      rpy="0 0 0" />
    <parent
      link="wrist_2_link" />
    <child
      link="wrist_3_link" />
    <axis
      xyz="1 0 0" />
    <limit
      lower="-3.14"
      upper="3.14"
      effort="28"
      velocity="3.2" />
  </joint>

  <!--new add content -->
  <!-- <joint name="ee_fixed_joint" type="fixed">
    <parent link="wrist_3_link"/>
    <child link="ee_link"/>
    <origin rpy="0.0 0.0 1.57079632679" xyz="0.0 0.04436 0.0"/>
  </joint>
  <link name="ee_link">
    <collision>
      <geometry>
        <box size="0.01 0.01 0.01"/>
      </geometry>
      <origin rpy="0 0 0" xyz="-0.01 0 0"/>
    </collision>
  </link> -->
	
      <!-- Frame coincident with all-zeros TCP on ROCR6 controller -->
  <link name="tool0"/>
  <joint name="wrist_3_link-tool0_fixed_joint" type="fixed">
    <origin rpy="-1.57079632679 0 0" xyz="0 0.04436 0"/>
    <parent link="wrist_3_link"/>
    <child link="tool0"/>
  </joint>

</robot>


